Workbook

Sheet Region
A1: Month3 | B1: Month | C1: Region | D1: Quintile Position | E1: Overall Rank | F1: Overall Score | G1: * | H1: GP Per Labor Hour Actual | I1: GP Per Labor Hour Tgt | J1: GP Per Labor Hour %Tgt | K1: GP Per Labor Hour Rank | L1: PP Acts | M1: PP Act Tgt | N1: PP Act %Tgt | O1: PP Act Attain Rank | P1: ReBiz Boxes | Q1: ReBiz Traffic | R1: Rebiz Conv | S1: Rebiz Conv Target | T1: ReBiz Conv %Tgt | U1: ReBiz Conv Rank | V1: Acc GP Pct Actual | W1: Acc GP Pct Rank | X1: CSAT Actual | Y1: CSAT Rank | Z1: New BAN Actual | AA1: New BAN Target | AB1: New BAN Attainment | AC1: New BAN Rank | AD1: Indexed P360 Attach Rate | AE1: P360 Attach Rate Tgt | AF1: P360 Attach Rate %Tgt | AG1: P360 Attach Rate Rank | AH1: Premium Lines | AI1: New Lines | AJ1: Premium Mix Rate | AK1: Premium Mix Rate Tgt | AL1: Premium Mix Rate %Tgt | AM1: Premium Rate Plan Rank | AN1: Premium Mix Rate %Tgt2 | AO1: Premium Rate Plan Rank3
A2: Month | B2: 10/2026 | C2: South | D2: 1 | E2: 1 | F2: 2.25 | G2: * | H2: 39.0962 | I2: 37.262867 | J2: 1.0492 | K2: 1 | L2: 11739.5 | M2: 13339.038 | N2: 0.880086 | O2: 4 | P2: 17191 | Q2: 91276 | R2: 0.18834086 | S2: 0.23703823 | T2: 0.794559 | U2: 1 | V2: 0.7304 | W2: 2 | X2: 8.8456 | Y2: 4 | Z2: 2817 | AA2: 3101.3846 | AB2: 0.9083 | AC2: 1 | AD2: 0.32239333 | AE2: 0.4 | AF2: 0.805982 | AG2: 3 | AH2: 2686 | AI2: 3516 | AJ2: 0.76393629 | AK2: 0.8 | AL2: 0.95492 | AM2: 3 | AN2: 1.00862 | AO2: 1
A3: Month | B3: 10/2026 | C3: North | D3: 2 | E3: 2 | F3: 2.35 | G3: * | H3: 32.3813 | I3: 32.738146 | J3: 0.9891 | K3: 4 | L3: 7873 | M3: 8642.8477 | N3: 0.910927 | O3: 2 | P3: 10640 | Q3: 58182 | R3: 0.18287443 | S3: 0.24000056 | T3: 0.761975 | U3: 2 | V3: 0.7868 | W3: 1 | X3: 9.0845 | Y3: 3 | Z3: 2114 | AA3: 2363.6066 | AB3: 0.8944 | AC3: 3 | AD3: 0.33019233 | AE3: 0.4 | AF3: 0.82548 | AG3: 2 | AH3: 1948 | AI3: 2388 | AJ3: 0.81574539 | AK3: 0.8 | AL3: 1.019681 | AM3: 1 | AN3: 0.999348 | AO3: 2
A4: Month | B4: 10/2026 | C4: East | D4: 3 | E4: 3 | F4: 2.6 | G4: * | H4: 34.9959 | I4: 35.164691 | J4: 0.9952 | K4: 3 | L4: 12698 | M4: 13265.209 | N4: 0.957241 | O4: 1 | P4: 16371 | Q4: 100173 | R4: 0.16342727 | S4: 0.2373337 | T4: 0.688597 | U4: 4 | V4: 0.6755 | W4: 4 | X4: 9.1447 | Y4: 1 | Z4: 2842 | AA4: 3190.5288 | AB4: 0.8908 | AC4: 4 | AD4: 0.36461967 | AE4: 0.4 | AF4: 0.911547 | AG4: 1 | AH4: 3066 | AI4: 3809 | AJ4: 0.80493568 | AK4: 0.8 | AL4: 1.006168 | AM4: 2 | AN4: 0.926723 | AO4: 3
A5: Month | B5: 10/2026 | C5: Central | D5: 4 | E5: 4 | F5: 2.8 | G5: * | H5: 37.8512 | I5: 37.000196 | J5: 1.023 | K5: 2 | L5: 11794 | M5: 13128.668 | N5: 0.898339 | O5: 3 | P5: 16606 | Q5: 99107 | R5: 0.16755628 | S5: 0.23926869 | T5: 0.700285 | U5: 3 | V5: 0.6925 | W5: 3 | X5: 9.0998 | Y5: 2 | Z5: 3004 | AA5: 3355.2345 | AB5: 0.8953 | AC5: 2 | AD5: 0.29746167 | AE5: 0.4 | AF5: 0.743652 | AG5: 4 | AH5: 2475 | AI5: 3319 | AJ5: 0.74570654 | AK5: 0.8 | AL5: 0.932132 | AM5: 4 | AN5: 0.919401 | AO5: 4

Sheet District
A1: Region | B1: Month | C1: District | D1: Quintile Position | E1: Overall Rank | F1: Overall Score | G1: * | H1: GP Per Labor Hour Actual | I1: GP Per Labor Hour Tgt | J1: GP Per Labor Hour %Tgt | K1: GP Per Labor Hour Rank | L1: PP Acts | M1: PP Act Tgt | N1: PP Act %Tgt | O1: PP Act Attain Rank | P1: ReBiz Boxes | Q1: ReBiz Traffic | R1: Rebiz Conv | S1: Rebiz Conv Target | T1: ReBiz Conv %Tgt | U1: ReBiz Conv Rank | V1: Acc GP Pct Actual | W1: Acc GP Pct Rank | X1: CSAT Actual | Y1: CSAT Rank | Z1: New BAN Actual | AA1: New BAN Target | AB1: New BAN Attainment | AC1: New BAN Rank | AD1: Indexed P360 Attach Rate | AE1: P360 Attach Rate Tgt | AF1: P360 Attach Rate %Tgt | AG1: P360 Attach Rate Rank | AH1: Premium Lines | AI1: New Lines | AJ1: Premium Mix Rate | AK1: Premium Mix Rate Tgt | AL1: Premium Mix Rate %Tgt | AM1: Premium Rate Plan Rank
A2: Central | B2: 10/2026 | C2: West Texas | D2: 1 | E2: 6 | F2: 11.7 | G2: * | H2: 53.3393 | I2: 37.499508 | J2: 1.4224 | K2: 2 | L2: 959 | M2: 955.1746 | N2: 1.004005 | O2: 10 | P2: 1245 | Q2: 7646 | R2: 0.16283024 | S2: 0.24000047 | T2: 0.678458 | U2: 28 | V2: 0.8021 | W2: 7 | X2: 9.0179 | Y2: 20 | Z2: 321 | AA2: 278.4709 | AB2: 1.1527 | AC2: 2 | AD2: 0.35993867 | AE2: 0.4 | AF2: 0.899845 | AG2: 9 | AH2: 210 | AI2: 272 | AJ2: 0.77205882 | AK2: 0.8 | AL2: 0.965072 | AM2: 18
A3: Central | B3: 10/2026 | C3: SA South | D3: 2 | E3: 8 | F3: 12.95 | G3: * | H3: 42.9261 | I3: 37.499869 | J3: 1.1447 | K3: 7 | L3: 1260.5 | M3: 1236.0539 | N3: 1.019778 | O3: 7 | P3: 1772 | Q3: 10911 | R3: 0.16240491 | S3: 0.23250158 | T3: 0.698511 | U3: 24 | V3: 0.771 | W3: 10 | X3: 9.1061 | Y3: 15 | Z3: 355 | AA3: 337.9007 | AB3: 1.0506 | AC3: 3 | AD3: 0.349259 | AE3: 0.4 | AF3: 0.873147 | AG3: 10 | AH3: 243 | AI3: 345 | AJ3: 0.70434783 | AK3: 0.8 | AL3: 0.880433 | AM3: 33
A4: Central | B4: 10/2026 | C4: South TX/RGV | D4: 2 | E4: 10 | F4: 13.95 | G4: * | H4: 47.9843 | I4: 36.665622 | J4: 1.3087 | K4: 3 | L4: 1385 | M4: 1447.9772 | N4: 0.956507 | O4: 14 | P4: 1961 | Q4: 10095 | R4: 0.19425458 | S4: 0.24000092 | T4: 0.809391 | U4: 9 | V4: 0.6933 | W4: 26 | X4: 9.1405 | Y4: 13 | Z4: 313 | AA4: 325.1656 | AB4: 0.9626 | AC4: 7 | AD4: 0.33644467 | AE4: 0.4 | AF4: 0.84111 | AG4: 16 | AH4: 239 | AI4: 360 | AJ4: 0.66388889 | AK4: 0.8 | AL4: 0.82986 | AM4: 35
A5: Central | B5: 10/2026 | C5: SA/Hill Country | D5: 4 | E5: 23 | F5: 21.35 | G5: * | H5: 35.6299 | I5: 37.855822 | J5: 0.9412 | K5: 29 | L5: 891 | M5: 996.2651 | N5: 0.89434 | O5: 23 | P5: 1359 | Q5: 7328 | R5: 0.18545306 | S5: 0.24000033 | T5: 0.77272 | U5: 10 | V5: 0.7659 | W5: 12 | X5: 9.4764 | Y5: 3 | Z5: 208 | AA5: 246.209 | AB5: 0.8448 | AC5: 27 | AD5: 0.23190667 | AE5: 0.4 | AF5: 0.579765 | AG5: 37 | AH5: 188 | AI5: 255 | AJ5: 0.7372549 | AK5: 0.8 | AL5: 0.921567 | AM5: 28
A6: Central | B6: 10/2026 | C6: KS/OK | D6: 4 | E6: 24 | F6: 21.65 | G6: * | H6: 38.0685 | I6: 39.09273 | J6: 0.9738 | K6: 22 | L6: 1820 | M6: 2168.9833 | N6: 0.839103 | O6: 29 | P6: 2600 | Q6: 14584 | R6: 0.17827756 | S6: 0.24000103 | T6: 0.74282 | U6: 16 | V6: 0.7037 | W6: 23 | X6: 9.2316 | Y6: 7 | Z6: 412 | AA6: 546.7538 | AB6: 0.7535 | AC6: 36 | AD6: 0.30964967 | AE6: 0.4 | AF6: 0.774122 | AG6: 25 | AH6: 345 | AI6: 400 | AJ6: 0.8625 | AK6: 0.8 | AL6: 1.078125 | AM6: 7
A7: Central | B7: 10/2026 | C7: MO/IA/NE | D7: 4 | E7: 29 | F7: 23.25 | G7: * | H7: 38.6806 | I7: 34.998733 | J7: 1.1052 | K7: 9 | L7: 1480 | M7: 1535.0083 | N7: 0.964164 | O7: 13 | P7: 1907 | Q7: 11032 | R7: 0.17286077 | S7: 0.24000107 | T7: 0.72025 | U7: 20 | V7: 0.5914 | W7: 34 | X7: 8.6766 | Y7: 34 | Z7: 291 | AA7: 408.3674 | AB7: 0.7126 | AC7: 37 | AD7: 0.29927167 | AE7: 0.4 | AF7: 0.748177 | AG7: 27 | AH7: 265 | AI7: 348 | AJ7: 0.76149425 | AK7: 0.8 | AL7: 0.951867 | AM7: 19
A8: Central | B8: 10/2026 | C8: DFW North | D8: 5 | E8: 33 | F8: 26.35 | G8: * | H8: 30.7191 | I8: 37.002048 | J8: 0.8302 | K8: 34 | L8: 1123.5 | M8: 1296.8973 | N8: 0.866298 | O8: 24 | P8: 1596 | Q8: 10855 | R8: 0.14702902 | S8: 0.24000036 | T8: 0.61262 | U8: 34 | V8: 0.6311 | W8: 32 | X8: 9.1103 | Y8: 14 | Z8: 352 | AA8: 380.3505 | AB8: 0.9255 | AC8: 11 | AD8: 0.27148 | AE8: 0.4 | AF8: 0.6787 | AG8: 33 | AH8: 276 | AI8: 381 | AJ8: 0.72440945 | AK8: 0.8 | AL8: 0.905511 | AM8: 30
A9: Central | B9: 10/2026 | C9: Central Texas | D9: 5 | E9: 34 | F9: 26.7 | G9: * | H9: 29.7505 | I9: 35.908871 | J9: 0.8285 | K9: 35 | L9: 1077 | M9: 1342.8958 | N9: 0.801998 | O9: 32 | P9: 1625 | Q9: 10109 | R9: 0.16074785 | S9: 0.24000133 | T9: 0.669779 | U9: 30 | V9: 0.667 | W9: 29 | X9: 9.1993 | Y9: 10 | Z9: 354 | AA9: 387.9914 | AB9: 0.9124 | AC9: 15 | AD9: 0.29314033 | AE9: 0.4 | AF9: 0.73285 | AG9: 28 | AH9: 303 | AI9: 421 | AJ9: 0.71971496 | AK9: 0.8 | AL9: 0.899642 | AM9: 32
A10: Central | B10: 10/2026 | C10: DFW East | D10: 5 | E10: 35 | F10: 27.85 | G10: * | H10: 34.739 | I10: 37.999344 | J10: 0.9142 | K10: 31 | L10: 1798 | M10: 2149.4125 | N10: 0.836508 | O10: 30 | P10: 2541 | Q10: 16547 | R10: 0.15356258 | S10: 0.24000116 | T10: 0.639841 | U10: 32 | V10: 0.6717 | W10: 28 | X10: 8.8531 | Y10: 28 | Z10: 398 | AA10: 444.0252 | AB10: 0.8963 | AC10: 16 | AD10: 0.24970533 | AE10: 0.4 | AF10: 0.624262 | AG10: 36 | AH10: 406 | AI10: 537 | AJ10: 0.75605214 | AK10: 0.8 | AL10: 0.945065 | AM10: 23

Sheet Store
A1: District | B1: SAP | C1: Month | D1: Sap: Loaction | E1: Quintile Position | F1: Overall Rank | G1: Overall Score | H1: * | I1: GP Per Labor Hour Actual | J1: GP Per Labor Hour Tgt | K1: GP Per Labor Hour %Tgt | L1: GP Per Labor Hour Rank | M1: PP Acts | N1: PP Act Tgt | O1: PP Act %Tgt | P1: PP Act Attain Rank | Q1: ReBiz Boxes | R1: ReBiz Traffic | S1: Rebiz Conv | T1: Rebiz Conv Target | U1: ReBiz Conv %Tgt | V1: ReBiz Conv Rank | W1: Acc GP Pct Actual | X1: Acc GP Pct Rank | Y1: CSAT Actual | Z1: CSAT Rank | AA1: New BAN Actual | AB1: New BAN Target | AC1: New BAN Attainment | AD1: New BAN Rank | AE1: Indexed P360 Attach Rate | AF1: P360 Attach Rate Tgt | AG1: P360 Attach Rate %Tgt | AH1: P360 Attach Rate Rank | AI1: Premium Lines | AJ1: New Lines | AK1: Premium Mix Rate | AL1: Premium Mix Rate Tgt | AM1: Premium Mix Rate %Tgt | AN1: Premium Rate Plan Rank
A2: =_xlfn.XLOOKUP(Table1[[#This Row],[SAP]],'Location List'!B:B,'Location List'!G:G) -> SA SOUTH | B2: =LEFT(Table1[[#This Row],[Sap: Loaction]],4) -> 1627 | C2: 10/2026 | D2: 1627: Marbach | E2: 1 | F2: 12 | G2: 71.15 | H2: * | I2: 51.1741 | J2: 39.998515 | K2: 1.2794 | L2: 66 | M2: 292 | N2: 255.4277 | O2: 1.1432 | P2: 55 | Q2: 386 | R2: 1692 | S2: 0.22813239 | T2: 0.23998778 | U2: 0.9506 | V2: 44 | W2: 0.86483619 | X2: 77 | Y2: 9.8644 | Z2: 26 | AA2: 68 | AB2: 60.2788 | AC2: 1.1281 | AD2: 42 | AE2: 0.32745833 | AF2: 0.4 | AG2: 0.8186 | AH2: 163 | AI2: 64 | AJ2: 76 | AK2: 0.84210526 | AL2: 0.8 | AM2: 1.0526 | AN2: 135
A3: =_xlfn.XLOOKUP(Table1[[#This Row],[SAP]],'Location List'!B:B,'Location List'!G:G) -> SOUTH TX/RGV | B3: =LEFT(Table1[[#This Row],[Sap: Loaction]],4) -> 2584 | C3: 10/2026 | D3: 2584: North Conway | E3: 1 | F3: 16 | G3: 74.6 | H3: * | I3: 63.0338 | J3: 40.001142 | K3: 1.5758 | L3: 19 | M3: 372 | N3: 344.1111 | O3: 1.081 | P3: 78 | Q3: 487 | R3: 2432 | S3: 0.20024671 | T3: 0.23998887 | U3: 0.8344 | V3: 80 | W3: 0.90512221 | X3: 61 | Y3: 9.5614 | Z3: 70 | AA3: 67 | AB3: 52.6378 | AC3: 1.2728 | AD3: 15 | AE3: 0.37789967 | AF3: 0.4 | AG3: 0.9447 | AH3: 105 | AI3: 56 | AJ3: 77 | AK3: 0.72727273 | AL3: 0.8 | AM3: 0.9091 | AN3: 222
A4: =_xlfn.XLOOKUP(Table1[[#This Row],[SAP]],'Location List'!B:B,'Location List'!G:G) -> WEST TEXAS | B4: =LEFT(Table1[[#This Row],[Sap: Loaction]],4) -> 903E | C4: 10/2026 | D4: 903E: Olton | E4: 1 | F4: 20 | G4: 83.1 | H4: * | I4: 39.7111 | J4: 30.000076 | K4: 1.3237 | L4: 54 | M4: 121 | N4: 85.4139 | O4: 1.4166 | P4: 8 | Q4: 158 | R4: 982 | S4: 0.16089613 | T4: 0.24000019 | U4: 0.6704 | V4: 203 | W4: 1.1792196 | X4: 11 | Y4: 8.6842 | Z4: 244 | AA4: 43 | AB4: 23.7719 | AC4: 1.8089 | AD4: 3 | AE4: 0.43655133 | AF4: 0.4 | AG4: 1.0914 | AH4: 39 | AI4: 32 | AJ4: 38 | AK4: 0.84210526 | AL4: 0.8 | AM4: 1.0526 | AN4: 135
A5: =_xlfn.XLOOKUP(Table1[[#This Row],[SAP]],'Location List'!B:B,'Location List'!G:G) -> SA SOUTH | B5: =LEFT(Table1[[#This Row],[Sap: Loaction]],4) -> 4723 | C5: 10/2026 | D5: 4723: Palo Alto | E5: 1 | F5: 31 | G5: 97.45 | H5: * | I5: 55.8597 | J5: 39.999785 | K5: 1.3965 | L5: 37 | M5: 227 | N5: 173.3041 | O5: 1.3098 | P5: 21 | Q5: 286 | R5: 1406 | S5: 0.20341394 | T5: 0.23998813 | U5: 0.8476 | V5: 74 | W5: 0.71274815 | X5: 170 | Y5: 8.84 | Z5: 219 | AA5: 46 | AB5: 39.0538 | AC5: 1.1779 | AD5: 27 | AE5: 0.42796567 | AF5: 0.4 | AG5: 1.0699 | AH5: 50 | AI5: 30 | AJ5: 53 | AK5: 0.56603774 | AL5: 0.8 | AM5: 0.7075 | AN5: 297
A6: =_xlfn.XLOOKUP(Table1[[#This Row],[SAP]],'Location List'!B:B,'Location List'!G:G) -> WEST TEXAS | B6: =LEFT(Table1[[#This Row],[Sap: Loaction]],4) -> 930E | C6: 10/2026 | D6: 930E: Big Spring | E6: 1 | F6: 36 | G6: 101.15 | H6: * | I6: 51.4546 | J6: 39.998912 | K6: 1.2864 | L6: 63 | M6: 147 | N6: 156.0431 | O6: 0.942 | P6: 145 | Q6: 208 | R6: 961 | S6: 0.21644121 | T6: 0.24001021 | U6: 0.9018 | V6: 55 | W6: 0.71503849 | X6: 167 | Y6: 9.8718 | Z6: 25 | AA6: 56 | AB6: 46.6948 | AC6: 1.1993 | AD6: 26 | AE6: 0.29725333 | AF6: 0.4 | AG6: 0.7431 | AH6: 203 | AI6: 36 | AJ6: 46 | AK6: 0.7826087 | AL6: 0.8 | AM6: 0.9783 | AN6: 183
A7: =_xlfn.XLOOKUP(Table1[[#This Row],[SAP]],'Location List'!B:B,'Location List'!G:G) -> WEST TEXAS | B7: =LEFT(Table1[[#This Row],[Sap: Loaction]],4) -> 1FSZ | C7: 10/2026 | D7: 1FSZ: S. Georgia | E7: 1 | F7: 39 | G7: 104.45 | H7: * | I7: 58.0286 | J7: 40.000414 | K7: 1.4507 | L7: 33 | M7: 300 | N7: 281.6994 | O7: 1.065 | P7: 82 | Q7: 336 | R7: 2171 | S7: 0.15476739 | T7: 0.23998665 | U7: 0.6449 | V7: 224 | W7: 0.87418539 | X7: 71 | Y7: 9.3077 | Z7: 115 | AA7: 93 | AB7: 73.0137 | AC7: 1.2737 | AD7: 14 | AE7: 0.332471 | AF7: 0.4 | AG7: 0.8312 | AH7: 158 | AI7: 66 | AJ7: 83 | AK7: 0.79518072 | AL7: 0.8 | AM7: 0.994 | AN7: 171
A8: =_xlfn.XLOOKUP(Table1[[#This Row],[SAP]],'Location List'!B:B,'Location List'!G:G) -> DFW NORTH | B8: =LEFT(Table1[[#This Row],[Sap: Loaction]],4) -> 256E | C8: 10/2026 | D8: 256E: Stephenville | E8: 1 | F8: 40 | G8: 104.5 | H8: * | I8: 38.0102 | J8: 35.000184 | K8: 1.086 | L8: 120 | M8: 141 | N8: 100.2059 | O8: 1.4071 | P8: 9 | Q8: 179 | R8: 740 | S8: 0.24189189 | T8: 0.23999592 | U8: 1.0079 | V8: 29 | W8: 0.75175132 | X8: 140 | Y8: 9.6842 | Z8: 44 | AA8: 36 | AB8: 33.1109 | AC8: 1.0873 | AD8: 52 | AE8: 0.19573133 | AF8: 0.4 | AG8: 0.4893 | AH8: 308 | AI8: 32 | AJ8: 46 | AK8: 0.69565217 | AL8: 0.8 | AM8: 0.8696 | AN8: 238
A9: =_xlfn.XLOOKUP(Table1[[#This Row],[SAP]],'Location List'!B:B,'Location List'!G:G) -> KS/OK | B9: =LEFT(Table1[[#This Row],[Sap: Loaction]],4) -> 586D | C9: 10/2026 | D9: 586D: Ardmore | E9: 1 | F9: 46 | G9: 111.5 | H9: * | I9: 52.4557 | J9: 39.999771 | K9: 1.3114 | L9: 58 | M9: 186 | N9: 186.4338 | O9: 0.9977 | P9: 113 | Q9: 280 | R9: 1489 | S9: 0.18804567 | T9: 0.24000723 | U9: 0.7835 | V9: 114 | W9: 0.9443369 | X9: 50 | Y9: 9.4828 | Z9: 83 | AA9: 38 | AB9: 44.1478 | AC9: 0.8607 | AD9: 177 | AE9: 0.26712067 | AF9: 0.4 | AG9: 0.6678 | AH9: 246 | AI9: 28 | AJ9: 29 | AK9: 0.96551724 | AL9: 0.8 | AM9: 1.2069 | AN9: 43
A10: =_xlfn.XLOOKUP(Table1[[#This Row],[SAP]],'Location List'!B:B,'Location List'!G:G) -> SOUTH TX/RGV | B10: =LEFT(Table1[[#This Row],[Sap: Loaction]],4) -> 216E | C10: 10/2026 | D10: 216E: Portland | E10: 1 | F10: 56 | G10: 117.45 | H10: * | I10: 52.5338 | J10: 40.001371 | K10: 1.3133 | L10: 57 | M10: 163 | N10: 155.2274 | O10: 1.0501 | P10: 86 | Q10: 253 | R10: 1274 | S10: 0.19858713 | T10: 0.24001345 | U10: 0.8274 | V10: 87 | W10: 0.67756677 | X10: 201 | Y10: 8.5 | Z10: 262 | AA10: 53 | AB10: 47.5438 | AC10: 1.1148 | AD10: 45 | AE10: 0.33300967 | AF10: 0.4 | AG10: 0.8325 | AH10: 157 | AI10: 40 | AJ10: 48 | AK10: 0.83333333 | AL10: 0.8 | AM10: 1.0417 | AN10: 142
A11: =_xlfn.XLOOKUP(Table1[[#This Row],[SAP]],'Location List'!B:B,'Location List'!G:G) -> KS/OK | B11: =LEFT(Table1[[#This Row],[Sap: Loaction]],4) -> 990F | C11: 10/2026 | D11: 990F: Wrangler | E11: 1 | F11: 62 | G11: 120.1 | H11: * | I11: 29.039 | J11: 39.998623 | K11: 0.726 | L11: 267 | M11: 157 | N11: 155.213 | O11: 1.0115 | P11: 106 | Q11: 200 | R11: 958 | S11: 0.20876827 | T11: 0.23999111 | U11: 0.8699 | V11: 69 | W11: 0.84879468 | X11: 84 | Y11: 9.5938 | Z11: 62 | AA11: 38 | AB11: 49.2418 | AC11: 0.7717 | AD11: 232 | AE11: 0.432985 | AF11: 0.4 | AG11: 1.0825 | AH11: 43 | AI11: 22 | AJ11: 22 | AK11: 1 | AL11: 0.8 | AM11: 1.25 | AN11: 1
A12: =_xlfn.XLOOKUP(Table1[[#This Row],[SAP]],'Location List'!B:B,'Location List'!G:G) -> MO/IA/NE | B12: =LEFT(Table1[[#This Row],[Sap: Loaction]],4) -> 3ISR | C12: 10/2026 | D12: 3ISR: Council Bluffs | E12: 1 | F12: 63 | G12: 121.25 | H12: * | I12: 65.1351 | J12: 39.999447 | K12: 1.6284 | L12: 16 | M12: 220 | N12: 214.3546 | O12: 1.0263 | P12: 100 | Q12: 277 | R12: 1288 | S12: 0.21506211 | T12: 0.23999789 | U12: 0.8961 | V12: 57 | W12: 0.53648519 | X12: 278 | Y12: 8.4 | Z12: 276 | AA12: 41 | AB12: 41.6008 | AC12: 0.9856 | AD12: 102 | AE12: 0.525334 | AF12: 0.4 | AG12: 1.3133 | AH12: 17 | AI12: 34 | AJ12: 48 | AK12: 0.70833333 | AL12: 0.8 | AM12: 0.8854 | AN12: 229
A13: =_xlfn.XLOOKUP(Table1[[#This Row],[SAP]],'Location List'!B:B,'Location List'!G:G) -> SA SOUTH | B13: =LEFT(Table1[[#This Row],[Sap: Loaction]],4) -> 1VSE | C13: 10/2026 | D13: 1VSE: Valley Hi | E13: 1 | F13: 65 | G13: 121.75 | H13: * | I13: 30.3126 | J13: 34.998961 | K13: 0.8661 | L13: 210 | M13: 123 | N13: 122.3716 | O13: 1.0051 | P13: 109 | Q13: 159 | R13: 898 | S13: 0.17706013 | T13: 0.23998392 | U13: 0.7378 | V13: 149 | W13: 0.99916566 | X13: 35 | Y13: 9.5455 | Z13: 72 | AA13: 28 | AB13: 34.8089 | AC13: 0.8044 | AD13: 211 | AE13: 0.433362 | AF13: 0.4 | AG13: 1.0834 | AH13: 42 | AI13: 23 | AJ13: 24 | AK13: 0.95833333 | AL13: 0.8 | AM13: 1.1979 | AN13: 50
... A83: =_xlfn.XLOOKUP(Table1[[#This Row],[SAP]],'Location List'!B:B,'Location List'!G:G) -> KS/OK | B83: =LEFT(Table1[[#This Row],[Sap: Loaction]],4) -> 849C | C83: 10/2026 | D83: 849C: George Washington | E83: 5 | F83: 334 | G83: 298.25 | H83: * | I83: 18.2215 | J83: 40.003293 | K83: 0.4555 | L83: 330 | M83: 93 | N83: 220.1125 | O83: 0.4225 | P83: 328 | Q83: 145 | R83: 1347 | S83: 0.10764662 | T83: 0.24001477 | U83: 0.4485 | V83: 329 | W83: 0.48848854 | X83: 301 | Y83: 8.9231 | Z83: 204 | AA83: 29 | AB83: 52.6378 | AC83: 0.5509 | AD83: 318 | AE83: 0.28735333 | AF83: 0.4 | AG83: 0.7184 | AH83: 214 | AI83: 13 | AJ83: 24 | AK83: 0.54166667 | AL83: 0.8 | AM83: 0.6771 | AN83: 306

Sheet Employee
A1: District | B1: SAP | C1: Title | D1: Month | E1: Employee | F1: Sap: Loaction | G1: Quintile Position | H1: Overall Rank | I1: Overall Score | J1: * | K1: GP Per Labor Hour Actual | L1: GP Per Labor Hour Tgt | M1: GP Per Labor Hour %Tgt | N1: GP Per Labor Hour Rank | O1: ReBiz Acts | P1: ReBiz Act Traffic | Q1: ReBiz Act Conv | R1: ReBiz Act Conv Tgt | S1: ReBiz Act Conv %Tgt | T1: ReBiz Act Conv Rank | U1: ReBiz Upgrades | V1: ReBiz Traffic | W1: ReBiz Upg Conv | X1: ReBiz Upg Conv Tgt | Y1: ReBiz Upg Conv %Tgt | Z1: ReBiz Upg Conv Rank | AA1: Acc Per Phone Actual | AB1: Acc Per Phone Rank | AC1: CSAT Actual | AD1: CSAT Rank | AE1: New BAN Actual | AF1: New BAN Target | AG1: New BAN Attainment | AH1: New BAN Rank | AI1: Indexed P360 Attach Rate | AJ1: P360 Attach Rate Tgt | AK1: P360 Attach Rate %Tgt | AL1: P360 Attach Rate Rank | AM1: Premium Lines | AN1: New Lines | AO1: Premium Mix Rate | AP1: Premium Mix Rate Tgt | AQ1: Premium Mix Rate %Tgt | AR1: Premium Rate Plan Rank | AS1: Premium Mix Rate %Tgt2 | AT1: Premium Rate Plan Rank3
A2: =_xlfn.XLOOKUP(Table13[[#This Row],[SAP]],'Location List'!B:B,'Location List'!G:G) -> WEST TEXAS | B2: =LEFT(Table13[[#This Row],[Sap: Loaction]],4) -> 903E | C2: =_xlfn.XLOOKUP(Table13[[#This Row],[Employee]],'Location List'!M:M,'Location List'!N:N,"",0) | D2: 10/2026 | E2: CAITLIN NINO(127673) | F2: 903E: Olton | G2: 1 | H2: 24 | I2: 280.55 | J2: * | K2: 69.05 | L2: 30 | M2: 2.3016667 | N2: 39 | O2: 19 | P2: 107 | Q2: 0.17757009 | R2: 0.19 | S2: 0.934578 | T2: 464 | U2: 0 | V2: 107 | W2: 0 | X2: 0.05 | Y2: 0 | Z2: 1312 | AA2: 1.888888 | AB2: 253 | AC2: 9 | AD2: 63 | AE2: 43 | AF2: 23.7719 | AG2: 1.8089 | AH2: 8 | AI2: 0.553571 | AJ2: 0.4 | AK2: 1.383927 | AL2: 178 | AM2: 9 | AN2: 9 | AO2: 1 | AP2: 0.8 | AQ2: 1.25 | AR2: 1 | AS2: 1.25 | AT2: 1
A3: =_xlfn.XLOOKUP(Table13[[#This Row],[SAP]],'Location List'!B:B,'Location List'!G:G) -> WEST TEXAS | B3: =LEFT(Table13[[#This Row],[Sap: Loaction]],4) -> 903E | C3: =_xlfn.XLOOKUP(Table13[[#This Row],[Employee]],'Location List'!M:M,'Location List'!N:N,"",0) | D3: 10/2026 | E3: JOEY CANTU(128224) | F3: 903E: Olton | G3: 1 | H3: 35 | I3: 300.5 | J3: * | K3: 68.65 | L3: 30 | M3: 2.2883333 | N3: 42 | O3: 30 | P3: 162 | Q3: 0.18518519 | R3: 0.19 | S3: 0.974657 | T3: 418 | U3: 3 | V3: 162 | W3: 0.018518519 | X3: 0.05 | Y3: 0.37036 | Z3: 834 | AA3: 1.076923 | AB3: 838 | AC3: 10 | AD3: 1 | AE3: 43 | AF3: 23.7719 | AG3: 1.8089 | AH3: 8 | AI3: 0.41666667 | AJ3: 0.4 | AK3: 1.041665 | AL3: 420 | AM3: 15 | AN3: 15 | AO3: 1 | AP3: 0.8 | AQ3: 1.25 | AR3: 1 | AS3: 1.25 | AT3: 1
A4: =_xlfn.XLOOKUP(Table13[[#This Row],[SAP]],'Location List'!B:B,'Location List'!G:G) -> SOUTH TX/RGV | B4: =LEFT(Table13[[#This Row],[Sap: Loaction]],4) -> 2584 | C4: =_xlfn.XLOOKUP(Table13[[#This Row],[Employee]],'Location List'!M:M,'Location List'!N:N,"",0) | D4: 10/2026 | E4: RODRIGO GLORIA(129756) | F4: 2584: North Conway | G4: 1 | H4: 37 | I4: 302.15 | J4: * | K4: 123.78 | L4: 40 | M4: 3.0945 | N4: 10 | O4: 159 | P4: 510 | Q4: 0.31176471 | R4: 0.19 | S4: 1.640863 | T4: 81 | U4: 12 | V4: 510 | W4: 0.023529412 | X4: 0.05 | Y4: 0.47058 | Z4: 677 | AA4: 1.305555 | AB4: 629 | AC4: 9 | AD4: 63 | AE4: 67 | AF4: 52.6378 | AG4: 1.2728 | AH4: 65 | AI4: 0.42766833 | AJ4: 0.4 | AK4: 1.06917 | AL4: 399 | AM4: 15 | AN4: 24 | AO4: 0.625 | AP4: 0.8 | AQ4: 0.78125 | AR4: 979 | AS4: 1.25 | AT4: 1
A5: =_xlfn.XLOOKUP(Table13[[#This Row],[SAP]],'Location List'!B:B,'Location List'!G:G) -> SA SOUTH | B5: =LEFT(Table13[[#This Row],[Sap: Loaction]],4) -> 1ESL | C5: =_xlfn.XLOOKUP(Table13[[#This Row],[Employee]],'Location List'!M:M,'Location List'!N:N,"",0) | D5: 10/2026 | E5: KEMBERLY MATA(130006) | F5: 1ESL: South Park Mall | G5: 1 | H5: 40 | I5: 304.8 | J5: * | K5: 69.1 | L5: 35 | M5: 1.9742857 | N5: 81 | O5: 47 | P5: 254 | Q5: 0.18503937 | R5: 0.19 | S5: 0.973889 | T5: 421 | U5: 9 | V5: 254 | W5: 0.035433071 | X5: 0.05 | Y5: 0.70866 | Z5: 374 | AA5: 1.666666 | AB5: 349 | AC5: 9 | AD5: 63 | AE5: 36 | AF5: 29.7149 | AG5: 1.2115 | AH5: 101 | AI5: 0.5 | AJ5: 0.4 | AK5: 1.25 | AL5: 242 | AM5: 2 | AN5: 3 | AO5: 0.66666667 | AP5: 0.8 | AQ5: 0.833332 | AR5: 905 | AS5: 1.25 | AT5: 1
A6: =_xlfn.XLOOKUP(Table13[[#This Row],[SAP]],'Location List'!B:B,'Location List'!G:G) -> SA SOUTH | B6: =LEFT(Table13[[#This Row],[Sap: Loaction]],4) -> 4723 | C6: =_xlfn.XLOOKUP(Table13[[#This Row],[Employee]],'Location List'!M:M,'Location List'!N:N,"",0) | D6: 10/2026 | E6: JAMES ACEVES(117082) | F6: 4723: Palo Alto | G6: 1 | H6: 53 | I6: 316.45 | J6: * | K6: 71.06 | L6: 40 | M6: 1.7765 | N6: 142 | O6: 67 | P6: 308 | Q6: 0.21753247 | R6: 0.19 | S6: 1.144905 | T6: 278 | U6: 13 | V6: 308 | W6: 0.042207792 | X6: 0.05 | Y6: 0.84414 | Z6: 260 | AA6: 1.918918 | AB6: 240 | AC6: 8 | AD6: 106 | AE6: 46 | AF6: 39.0538 | AG6: 1.1779 | AH6: 121 | AI6: 0.32777767 | AJ6: 0.4 | AK6: 0.819442 | AL6: 703 | AM6: 8 | AN6: 12 | AO6: 0.66666667 | AP6: 0.8 | AQ6: 0.833332 | AR6: 905 | AS6: 0 | AT6: 501
A7: =_xlfn.XLOOKUP(Table13[[#This Row],[SAP]],'Location List'!B:B,'Location List'!G:G) -> DFW EAST | B7: =LEFT(Table13[[#This Row],[Sap: Loaction]],4) -> 875E | C7: =_xlfn.XLOOKUP(Table13[[#This Row],[Employee]],'Location List'!M:M,'Location List'!N:N,"",0) | D7: 10/2026 | E7: SEAN ARINZE(128820) | F7: 875E: Custer | G7: 1 | H7: 61 | I7: 332.05 | J7: * | K7: 81.43 | L7: 35 | M7: 2.3265714 | N7: 37 | O7: 57 | P7: 119 | Q7: 0.4789916 | R7: 0.19 | S7: 2.521005 | T7: 7 | U7: 6 | V7: 119 | W7: 0.050420168 | X7: 0.05 | Y7: 1.0084 | Z7: 165 | AA7: 1.44 | AB7: 513 | AC7: 8.5 | AD7: 87 | AE7: 17 | AF7: 27.1679 | AG7: 0.6257 | AH7: 1312 | AI7: 0.29282725 | AJ7: 0.4 | AK7: 0.962472 | AL7: 517 | AM7: 21 | AN7: 21 | AO7: 1 | AP7: 0.8 | AQ7: 1.25 | AR7: 1 | AS7: 1.25 | AT7: 1
A8: =_xlfn.XLOOKUP(Table13[[#This Row],[SAP]],'Location List'!B:B,'Location List'!G:G) -> SA SOUTH | B8: =LEFT(Table13[[#This Row],[Sap: Loaction]],4) -> 4723 | C8: =_xlfn.XLOOKUP(Table13[[#This Row],[Employee]],'Location List'!M:M,'Location List'!N:N,"",0) | D8: 10/2026 | E8: LIZBETH PEREZ FAVELA(127245) | F8: 4723: Palo Alto | G8: 1 | H8: 67 | I8: 334.85 | J8: * | K8: 104.59 | L8: 40 | M8: 2.61475 | N8: 24 | O8: 69 | P8: 155 | Q8: 0.44516129 | R8: 0.19 | S8: 2.342952 | T8: 12 | U8: 5 | V8: 155 | W8: 0.032258065 | X8: 0.05 | Y8: 0.64516 | Z8: 443 | AA8: 0.766666 | AB8: 1134 | AC8: 7.5 | AD8: 122 | AE8: 46 | AF8: 39.0538 | AG8: 1.1779 | AH8: 121 | AI8: 0.53333333 | AJ8: 0.4 | AK8: 1.333332 | AL8: 203 | AM8: 1 | AN8: 5 | AO8: 0.2 | AP8: 0.8 | AQ8: 0.25 | AR8: 1205 | AS8: 1.25 | AT8: 1
A9: =_xlfn.XLOOKUP(Table13[[#This Row],[SAP]],'Location List'!B:B,'Location List'!G:G) -> CENTRAL TEXAS | B9: =LEFT(Table13[[#This Row],[Sap: Loaction]],4) -> 1FSH | C9: =_xlfn.XLOOKUP(Table13[[#This Row],[Employee]],'Location List'!M:M,'Location List'!N:N,"",0) | D9: 10/2026 | E9: KATRINA KINDRED(110154) | F9: 1FSH: Manor | G9: 1 | H9: 71 | I9: 338 | J9: * | K9: 66.05 | L9: 40 | M9: 1.65125 | N9: 194 | O9: 36 | P9: 146 | Q9: 0.24657534 | R9: 0.19 | S9: 1.297763 | T9: 182 | U9: 11 | V9: 146 | W9: 0.075342466 | X9: 0.05 | Y9: 1.50684 | Z9: 31 | AA9: 0.777777 | AB9: 1124 | AC9: 7.5 | AD9: 122 | AE9: 64 | AF9: 51.7888 | AG9: 1.2358 | AH9: 86 | AI9: 0.421245 | AJ9: 0.4 | AK9: 1.053112 | AL9: 414 | AM9: 8 | AN9: 12 | AO9: 0.66666667 | AP9: 0.8 | AQ9: 0.833332 | AR9: 905 | AS9: 0.625 | AT9: 452
A10: =_xlfn.XLOOKUP(Table13[[#This Row],[SAP]],'Location List'!B:B,'Location List'!G:G) -> WEST TEXAS | B10: =LEFT(Table13[[#This Row],[Sap: Loaction]],4) -> 930E | C10: =_xlfn.XLOOKUP(Table13[[#This Row],[Employee]],'Location List'!M:M,'Location List'!N:N,"",0) -> RSM | D10: 10/2026 | E10: MARY RODRIGUEZ(126176) | F10: 930E: Big Spring | G10: 1 | H10: 75 | I10: 342.35 | J10: * | K10: 47.94 | L10: 40 | M10: 1.1985 | N10: 471 | O10: 32 | P10: 226 | Q10: 0.14159292 | R10: 0.19 | S10: 0.745221 | T10: 716 | U10: 12 | V10: 226 | W10: 0.053097345 | X10: 0.05 | Y10: 1.06194 | Z10: 138 | AA10: 2.12 | AB10: 179 | AC10: 10 | AD10: 1 | AE10: 56 | AF10: 46.6948 | AG10: 1.1993 | AH10: 116 | AI10: 0.55 | AJ10: 0.4 | AK10: 1.375 | AL10: 182 | AM10: 8 | AN10: 9 | AO10: 0.88888889 | AP10: 0.8 | AQ10: 1.11111 | AR10: 611 | AS10: 1.25 | AT10: 1
A11: =_xlfn.XLOOKUP(Table13[[#This Row],[SAP]],'Location List'!B:B,'Location List'!G:G) -> KS/OK | B11: =LEFT(Table13[[#This Row],[Sap: Loaction]],4) -> 114E | C11: =_xlfn.XLOOKUP(Table13[[#This Row],[Employee]],'Location List'!M:M,'Location List'!N:N,"",0) | D11: 10/2026 | E11: FINLEE WERNER(129078) | F11: 114E: Chickasha | G11: 1 | H11: 78 | I11: 348.45 | J11: * | K11: 36.41 | L11: 35 | M11: 1.0402857 | N11: 612 | O11: 60 | P11: 140 | Q11: 0.42857143 | R11: 0.19 | S11: 2.255636 | T11: 15 | U11: 6 | V11: 140 | W11: 0.042857143 | X11: 0.05 | Y11: 0.85714 | Z11: 250 | AA11: 1.545454 | AB11: 430 | AC11: 10 | AD11: 1 | AE11: 28 | AF11: 31.4129 | AG11: 0.8914 | AH11: 731 | AI11: 0.30555533 | AJ11: 0.4 | AK11: 0.763887 | AL11: 758 | AM11: 1 | AN11: 1 | AO11: 1 | AP11: 0.8 | AQ11: 1.25 | AR11: 1 | AS11: 0 | AT11: 501
A12: =_xlfn.XLOOKUP(Table13[[#This Row],[SAP]],'Location List'!B:B,'Location List'!G:G) -> SA/HILL COUNTRY | B12: =LEFT(Table13[[#This Row],[Sap: Loaction]],4) -> 776D | C12: =_xlfn.XLOOKUP(Table13[[#This Row],[Employee]],'Location List'!M:M,'Location List'!N:N,"",0) -> RSM | D12: 10/2026 | E12: DWAYNE PYLE(105026) | F12: 776D: Thousand Oaks | G12: 1 | H12: 81 | I12: 350.1 | J12: * | K12: 73.11 | L12: 35 | M12: 2.0888571 | N12: 62 | O12: 70 | P12: 189 | Q12: 0.37037037 | R12: 0.19 | S12: 1.949315 | T12: 36 | U12: 6 | V12: 189 | W12: 0.031746032 | X12: 0.05 | Y12: 0.63492 | Z12: 454 | AA12: 1.59375 | AB12: 413 | AC12: 10 | AD12: 1 | AE12: 24 | AF12: 27.1679 | AG12: 0.8834 | AH12: 752 | AI12: 0.017543667 | AJ12: 0.4 | AK12: 0.043857 | AL12: 1339 | AM12: 12 | AN12: 12 | AO12: 1 | AP12: 0.8 | AQ12: 1.25 | AR12: 1 | AS12: 0 | AT12: 501
A13: =_xlfn.XLOOKUP(Table13[[#This Row],[SAP]],'Location List'!B:B,'Location List'!G:G) -> WEST TEXAS | B13: =LEFT(Table13[[#This Row],[Sap: Loaction]],4) -> 930E | C13: =_xlfn.XLOOKUP(Table13[[#This Row],[Employee]],'Location List'!M:M,'Location List'!N:N,"",0) | D13: 10/2026 | E13: CHRISTEN RODRIGUEZ(126466) | F13: 930E: Big Spring | G13: 1 | H13: 85 | I13: 355.35 | J13: * | K13: 63.13 | L13: 40 | M13: 1.57825 | N13: 225 | O13: 46 | P13: 201 | Q13: 0.22885572 | R13: 0.19 | S13: 1.2045 | T13: 231 | U13: 12 | V13: 201 | W13: 0.059701493 | X13: 0.05 | Y13: 1.19402 | Z13: 74 | AA13: 1.2 | AB13: 722 | AC13: 9.444444 | AD13: 39 | AE13: 56 | AF13: 46.6948 | AG13: 1.1993 | AH13: 116 | AI13: 0.27719267 | AJ13: 0.4 | AK13: 0.69298 | AL13: 840 | AM13: 10 | AN13: 15 | AO13: 0.66666667 | AP13: 0.8 | AQ13: 0.833332 | AR13: 905 | AS13: 1.25 | AT13: 1
... A28: =_xlfn.XLOOKUP(Table13[[#This Row],[SAP]],'Location List'!B:B,'Location List'!G:G) -> SOUTH TX/RGV | B28: =LEFT(Table13[[#This Row],[Sap: Loaction]],4) -> 200E | C28: =_xlfn.XLOOKUP(Table13[[#This Row],[Employee]],'Location List'!M:M,'Location List'!N:N,"",0) | D28: 10/2026 | E28: JOHNSON DILLASHAW(129129) | F28: 200E: Rockport | G28: 1 | H28: 139 | I28: 390.85 | J28: * | K28: 76.19 | L28: 40 | M28: 1.90475 | N28: 97 | O28: 53 | P28: 209 | Q28: 0.25358852 | R28: 0.19 | S28: 1.334673 | T28: 164 | U28: 3 | V28: 209 | W28: 0.014354067 | X28: 0.05 | Y28: 0.28708 | Z28: 971 | AA28: 1.857142 | AB28: 269 | AC28: 9.4 | AD28: 42 | AE28: 41 | AF28: 41.6008 | AG28: 0.9856 | AH28: 466 | AI28: 0.42592567 | AJ28: 0.4 | AK28: 1.064812 | AL28: 404 | AM28: 5 | AN28: 10 | AO28: 0.5 | AP28: 0.8 | AQ28: 0.625 | AR28: 1050 | AS28: 1.25 | AT28: 1
A29: =_xlfn.XLOOKUP(Table13[[#This Row],[SAP]],'Location List'!B:B,'Location List'!G:G) -> SA SOUTH | B29: =LEFT(Table13[[#This Row],[Sap: Loaction]],4) -> 1627 | C29: =_xlfn.XLOOKUP(Table13[[#This Row],[Employee]],'Location List'!M:M,'Location List'!N:N,"",0) | D29: 10/2026 | E29: DAVID ALEMAN(126389) | F29: 1627: Marbach | G29: 1 | H29: 144 | I29: 394.05 | J29: * | K29: 61.34 | L29: 40 | M29: 1.5335 | N29: 245 | O29: 52 | P29: 198 | Q29: 0.26262626 | R29: 0.19 | S29: 1.382242 | T29: 144 | U29: 4 | V29: 198 | W29: 0.02020202 | X29: 0.05 | Y29: 0.40404 | Z29: 788 | AA29: 1.807692 | AB29: 292 | AC29: 10 | AD29: 1 | AE29: 68 | AF29: 60.2788 | AG29: 1.1281 | AH29: 182 | AJ29: 0.4 | AK29: 0 | AL29: 1340 | AM29: 9 | AN29: 10 | AO29: 0.9 | AP29: 0.8 | AQ29: 1.125 | AR29: 591 | AS29: 1.25 | AT29: 1
A30: =_xlfn.XLOOKUP(Table13[[#This Row],[SAP]],'Location List'!B:B,'Location List'!G:G) -> SA/HILL COUNTRY | B30: =LEFT(Table13[[#This Row],[Sap: Loaction]],4) -> 1ESB | C30: =_xlfn.XLOOKUP(Table13[[#This Row],[Employee]],'Location List'!M:M,'Location List'!N:N,"",0) | D30: 10/2026 | E30: ELIJAH MILLENDER(107137) | F30: 1ESB: Creekside | G30: 1 | H30: 150 | I30: 396.95 | J30: * | K30: 79.67 | L30: 40 | M30: 1.99175 | N30: 76 | O30: 55 | P30: 212 | Q30: 0.25943396 | R30: 0.19 | S30: 1.365436 | T30: 150 | U30: 11 | V30: 212 | W30: 0.051886792 | X30: 0.05 | Y30: 1.03772 | Z30: 148 | AA30: 0.705882 | AB30: 1187 | AC30: 9.5 | AD30: 37 | AE30: 44 | AF30: 47.5438 | AG30: 0.9255 | AH30: 619 | AI30: 0.347953 | AJ30: 0.4 | AK30: 0.869882 | AL30: 617 | AM30: 28 | AN30: 32 | AO30: 0.875 | AP30: 0.8 | AQ30: 1.09375 | AR30: 638 | AS30: 1.25 | AT30: 1
A31: =_xlfn.XLOOKUP(Table13[[#This Row],[SAP]],'Location List'!B:B,'Location List'!G:G) -> WEST TEXAS | B31: =LEFT(Table13[[#This Row],[Sap: Loaction]],4) -> 1FSZ | C31: =_xlfn.XLOOKUP(Table13[[#This Row],[Employee]],'Location List'!M:M,'Location List'!N:N,"",0) | D31: 10/2026 | E31: JEREMY GEIGER(129241) | F31: 1FSZ: S. Georgia | G31: 1 | H31: 166 | I31: 405.7 | J31: * | K31: 48.64 | L31: 40 | M31: 1.216 | N31: 453 | O31: 47 | P31: 300 | Q31: 0.15666667 | R31: 0.19 | S31: 0.824557 | T31: 609 | U31: 7 | V31: 300 | W31: 0.023333333 | X31: 0.05 | Y31: 0.46666 | Z31: 689 | AA31: 1.84 | AB31: 279 | AC31: 10 | AD31: 1 | AE31: 93 | AF31: 73.0137 | AG31: 1.2737 | AH31: 61 | AI31: 0.39529867 | AJ31: 0.4 | AK31: 0.988245 | AL31: 488 | AM31: 8 | AN31: 9 | AO31: 0.88888889 | AP31: 0.8 | AQ31: 1.11111 | AR31: 611 | AS31: 0 | AT31: 501
A32: =_xlfn.XLOOKUP(Table13[[#This Row],[SAP]],'Location List'!B:B,'Location List'!G:G) -> KS/OK | B32: =LEFT(Table13[[#This Row],[Sap: Loaction]],4) -> 5280 | C32: =_xlfn.XLOOKUP(Table13[[#This Row],[Employee]],'Location List'!M:M,'Location List'!N:N,"",0) | D32: 10/2026 | E32: JORDAN DAVIS(120751) | F32: 5280: Garth Brooks Blvd | G32: 1 | H32: 168 | I32: 408.25 | J32: * | K32: 59.46 | L32: 40 | M32: 1.4865 | N32: 271 | O32: 64 | P32: 329 | Q32: 0.19452888 | R32: 0.19 | S32: 1.023831 | T32: 361 | U32: 9 | V32: 329 | W32: 0.027355623 | X32: 0.05 | Y32: 0.5471 | Z32: 571 | AA32: 1.15625 | AB32: 768 | AC32: 8.5 | AD32: 87 | AE32: 41 | AF32: 42.4498 | AG32: 0.9658 | AH32: 526 | AI32: 0.313131 | AJ32: 0.4 | AK32: 0.782827 | AL32: 738 | AM32: 10 | AN32: 10 | AO32: 1 | AP32: 0.8 | AQ32: 1.25 | AR32: 1 | AS32: 1.25 | AT32: 1
A33: =_xlfn.XLOOKUP(Table13[[#This Row],[SAP]],'Location List'!B:B,'Location List'!G:G) -> SOUTH TX/RGV | B33: =LEFT(Table13[[#This Row],[Sap: Loaction]],4) -> 2584 | C33: =_xlfn.XLOOKUP(Table13[[#This Row],[Employee]],'Location List'!M:M,'Location List'!N:N,"",0) | D33: 10/2026 | E33: JOHN CADENA(126871) | F33: 2584: North Conway | G33: 1 | H33: 171 | I33: 410.25 | J33: * | K33: 68.79 | L33: 40 | M33: 1.71975 | N33: 158 | O33: 99 | P33: 540 | Q33: 0.18333333 | R33: 0.19 | S33: 0.96491 | T33: 430 | U33: 13 | V33: 540 | W33: 0.024074074 | X33: 0.05 | Y33: 0.48148 | Z33: 663 | AA33: 0.803921 | AB33: 1103 | AC33: 10 | AD33: 1 | AE33: 67 | AF33: 52.6378 | AG33: 1.2728 | AH33: 65 | AI33: 0.42604 | AJ33: 0.4 | AK33: 1.0651 | AL33: 403 | AM33: 12 | AN33: 15 | AO33: 0.8 | AP33: 0.8 | AQ33: 1 | AR33: 738 | AS33: 0 | AT33: 501
A34: =_xlfn.XLOOKUP(Table13[[#This Row],[SAP]],'Location List'!B:B,'Location List'!G:G) -> SA/HILL COUNTRY | B34: =LEFT(Table13[[#This Row],[Sap: Loaction]],4) -> 569D | C34: =_xlfn.XLOOKUP(Table13[[#This Row],[Employee]],'Location List'!M:M,'Location List'!N:N,"",0) | D34: 10/2026 | E34: JOSHUA PHILLIPS(128695) | F34: 569D: South Main | G34: 1 | H34: 173 | I34: 410.3 | J34: * | K34: 37.7 | L34: 35 | M34: 1.0771429 | N34: 583 | O34: 37 | P34: 212 | Q34: 0.1745283 | R34: 0.19 | S34: 0.918568 | T34: 487 | U34: 17 | V34: 212 | W34: 0.080188679 | X34: 0.05 | Y34: 1.60376 | Z34: 26 | AA34: 1.296296 | AB34: 637 | AC34: 10 | AD34: 1 | AE34: 20 | AF34: 23.7719 | AG34: 0.8413 | AH34: 853 | AI34: 0.47619033 | AJ34: 0.4 | AK34: 1.190475 | AL34: 310 | AM34: 6 | AN34: 6 | AO34: 1 | AP34: 0.8 | AQ34: 1.25 | AR34: 1 | AS34: 1.25 | AT34: 1
A35: =_xlfn.XLOOKUP(Table13[[#This Row],[SAP]],'Location List'!B:B,'Location List'!G:G) -> SA/HILL COUNTRY | B35: =LEFT(Table13[[#This Row],[Sap: Loaction]],4) -> 583D | C35: =_xlfn.XLOOKUP(Table13[[#This Row],[Employee]],'Location List'!M:M,'Location List'!N:N,"",0) | D35: 10/2026 | E35: MAURICIO GARZA(125726) | F35: 583D: Cibolo | G35: 1 | H35: 174 | I35: 410.65 | J35: * | K35: 49.26 | L35: 40 | M35: 1.2315 | N35: 439 | O35: 30 | P35: 198 | Q35: 0.15151515 | R35: 0.19 | S35: 0.797447 | T35: 639 | U35: 10 | V35: 198 | W35: 0.050505051 | X35: 0.05 | Y35: 1.0101 | Z35: 163 | AA35: 1.619047 | AB35: 390 | AC35: 9.857142 | AD35: 12 | AE35: 34 | AF35: 29.7149 | AG35: 1.1442 | AH35: 168 | AI35: 0.38888867 | AJ35: 0.4 | AK35: 0.97222 | AL35: 495 | AM35: 10 | AN35: 14 | AO35: 0.71428571 | AP35: 0.8 | AQ35: 0.892856 | AR35: 858 | AS35: 0.694443 | AT35: 451
A36: =_xlfn.XLOOKUP(Table13[[#This Row],[SAP]],'Location List'!B:B,'Location List'!G:G) -> KS/OK | B36: =LEFT(Table13[[#This Row],[Sap: Loaction]],4) -> 586D | C36: =_xlfn.XLOOKUP(Table13[[#This Row],[Employee]],'Location List'!M:M,'Location List'!N:N,"",0) | D36: 10/2026 | E36: KYLE NIPP(129086) | F36: 586D: Ardmore | G36: 1 | H36: 176 | I36: 411.75 | J36: * | K36: 68.55 | L36: 40 | M36: 1.71375 | N36: 161 | O36: 80 | P36: 302 | Q36: 0.26490066 | R36: 0.19 | S36: 1.39421 | T36: 142 | U36: 6 | V36: 302 | W36: 0.01986755 | X36: 0.05 | Y36: 0.39734 | Z36: 794 | AA36: 0.953488 | AB36: 957 | AC36: 10 | AD36: 1 | AE36: 38 | AF36: 44.1478 | AG36: 0.8607 | AH36: 814 | AI36: 0.34761867 | AJ36: 0.4 | AK36: 0.869045 | AL36: 618 | AM36: 9 | AN36: 9 | AO36: 1 | AP36: 0.8 | AQ36: 1.25 | AR36: 1 | AS36: 1.25 | AT36: 1
A37: =_xlfn.XLOOKUP(Table13[[#This Row],[SAP]],'Location List'!B:B,'Location List'!G:G) -> KS/OK | B37: =LEFT(Table13[[#This Row],[Sap: Loaction]],4) -> 966D | C37: =_xlfn.XLOOKUP(Table13[[#This Row],[Employee]],'Location List'!M:M,'Location List'!N:N,"",0) | D37: 10/2026 | E37: ASHLEY SHOEMAKER(122974) | F37: 966D: Sapulpa | G37: 1 | H37: 181 | I37: 413.85 | J37: * | K37: 71.65 | L37: 40 | M37: 1.79125 | N37: 137 | O37: 53 | P37: 234 | Q37: 0.22649573 | R37: 0.19 | S37: 1.192078 | T37: 240 | U37: 6 | V37: 234 | W37: 0.025641026 | X37: 0.05 | Y37: 0.51282 | Z37: 610 | AA37: 1.625 | AB37: 386 | AC37: 9.875 | AD37: 11 | AE37: 39 | AF37: 54.3358 | AG37: 0.7178 | AH37: 1168 | AI37: 0.33121667 | AJ37: 0.4 | AK37: 0.82804 | AL37: 693 | AM37: 9 | AN37: 9 | AO37: 1 | AP37: 0.8 | AQ37: 1.25 | AR37: 1 | AS37: 1.25 | AT37: 1
A38: =_xlfn.XLOOKUP(Table13[[#This Row],[SAP]],'Location List'!B:B,'Location List'!G:G) -> SA SOUTH | B38: =LEFT(Table13[[#This Row],[Sap: Loaction]],4) -> 1627 | C38: =_xlfn.XLOOKUP(Table13[[#This Row],[Employee]],'Location List'!M:M,'Location List'!N:N,"",0) | D38: 10/2026 | E38: SAVANNAH UTLEY(106365) | F38: 1627: Marbach | G38: 1 | H38: 184 | I38: 414.95 | J38: * | K38: 57.23 | L38: 40 | M38: 1.43075 | N38: 305 | O38: 53 | P38: 301 | Q38: 0.17607973 | R38: 0.19 | S38: 0.926731 | T38: 477 | U38: 5 | V38: 301 | W38: 0.016611296 | X38: 0.05 | Y38: 0.33222 | Z38: 902 | AA38: 2.222222 | AB38: 155 | AC38: 9.583333 | AD38: 31 | AE38: 68 | AF38: 60.2788 | AG38: 1.1281 | AH38: 182 | AI38: 0.304248 | AJ38: 0.4 | AK38: 0.76062 | AL38: 766 | AM38: 8 | AN38: 9 | AO38: 0.88888889 | AP38: 0.8 | AQ38: 1.11111 | AR38: 611 | AS38: 0 | AT38: 501
A39: =_xlfn.XLOOKUP(Table13[[#This Row],[SAP]],'Location List'!B:B,'Location List'!G:G) -> DFW NORTH | B39: =LEFT(Table13[[#This Row],[Sap: Loaction]],4) -> 5429 | C39: =_xlfn.XLOOKUP(Table13[[#This Row],[Employee]],'Location List'!M:M,'Location List'!N:N,"",0) | D39: 10/2026 | E39: ANNALEE STEPHEN(126209) | F39: 5429: Seventh Ave | G39: 1 | H39: 188 | I39: 417.35 | J39: * | K39: 63.51 | L39: 40 | M39: 1.58775 | N39: 218 | O39: 55 | P39: 235 | Q39: 0.23404255 | R39: 0.19 | S39: 1.2318 | T39: 212 | U39: 4 | V39: 235 | W39: 0.017021277 | X39: 0.05 | Y39: 0.34042 | Z39: 881 | AA39: 1.545454 | AB39: 430 | AC39: 10 | AD39: 1 | AE39: 64 | AF39: 60.2788 | AG39: 1.0617 | AH39: 283 | AI39: 0.17037033 | AJ39: 0.4 | AK39: 0.425925 | AL39: 1112 | AM39: 10 | AN39: 11 | AO39: 0.90909091 | AP39: 0.8 | AQ39: 1.136362 | AR39: 574 | AS39: 1.25 | AT39: 1
A40: =_xlfn.XLOOKUP(Table13[[#This Row],[SAP]],'Location List'!B:B,'Location List'!G:G) -> SA SOUTH | B40: =LEFT(Table13[[#This Row],[Sap: Loaction]],4) -> 4723 | C40: =_xlfn.XLOOKUP(Table13[[#This Row],[Employee]],'Location List'!M:M,'Location List'!N:N,"",0) | D40: 10/2026 | E40: MICHAEL GONZALES(127095) | F40: 4723: Palo Alto | G40: 1 | H40: 191 | I40: 420.45 | J40: * | K40: 67.8 | L40: 40 | M40: 1.695 | N40: 168 | O40: 55 | P40: 299 | Q40: 0.18394649 | R40: 0.19 | S40: 0.968136 | T40: 426 | U40: 5 | V40: 299 | W40: 0.016722408 | X40: 0.05 | Y40: 0.33444 | Z40: 894 | AA40: 1.192307 | AB40: 741 | AC40: 8.555555 | AD40: 86 | AE40: 46 | AF40: 39.0538 | AG40: 1.1779 | AH40: 121 | AI40: 0.55324067 | AJ40: 0.4 | AK40: 1.3831 | AL40: 180 | AM40: 8 | AN40: 14 | AO40: 0.57142857 | AP40: 0.8 | AQ40: 0.714285 | AR40: 1018 | AS40: 0 | AT40: 501
A41: =_xlfn.XLOOKUP(Table13[[#This Row],[SAP]],'Location List'!B:B,'Location List'!G:G) -> WEST TEXAS | B41: =LEFT(Table13[[#This Row],[Sap: Loaction]],4) -> 705D | C41: =_xlfn.XLOOKUP(Table13[[#This Row],[Employee]],'Location List'!M:M,'Location List'!N:N,"",0) | D41: 10/2026 | E41: AUDREY JOHNSON(126281) | F41: 705D: Midland | G41: 1 | H41: 192 | I41: 421.7 | J41: * | K41: 74.96 | L41: 40 | M41: 1.874 | N41: 105 | O41: 23 | P41: 123 | Q41: 0.18699187 | R41: 0.19 | S41: 0.984163 | T41: 401 | U41: 6 | V41: 123 | W41: 0.048780488 | X41: 0.05 | Y41: 0.9756 | Z41: 187 | AA41: 0.76923 | AB41: 1128 | AC41: 9.5 | AD41: 37 | AE41: 44 | AF41: 42.4498 | AG41: 1.0365 | AH41: 355 | AI41: 0.40079333 | AJ41: 0.4 | AK41: 1.001982 | AL41: 468 | AM41: 4 | AN41: 6 | AO41: 0.66666667 | AP41: 0.8 | AQ41: 0.833332 | AR41: 905 | AS41: 0 | AT41: 501
... A81: =_xlfn.XLOOKUP(Table13[[#This Row],[SAP]],'Location List'!B:B,'Location List'!G:G) -> CENTRAL TEXAS | B81: =LEFT(Table13[[#This Row],[Sap: Loaction]],4) -> 1FSH | C81: =_xlfn.XLOOKUP(Table13[[#This Row],[Employee]],'Location List'!M:M,'Location List'!N:N,"",0) | D81: 10/2026 | E81: PEDRO CASTRO(124783) | F81: 1FSH: Manor | G81: 2 | H81: 362 | I81: 498.3 | J81: * | K81: 55.22 | L81: 40 | M81: 1.3805 | N81: 344 | O81: 44 | P81: 360 | Q81: 0.12222222 | R81: 0.19 | S81: 0.643273 | T81: 858 | U81: 7 | V81: 360 | W81: 0.019444444 | X81: 0.05 | Y81: 0.38888 | Z81: 808 | AA81: 1.76923 | AB81: 311 | AC81: 9.777777 | AD81: 17 | AE81: 64 | AF81: 51.7888 | AG81: 1.2358 | AH81: 86 | AI81: 0.2499998 | AJ81: 0.4 | AK81: 0.72222 | AL81: 804 | AM81: 11 | AN81: 13 | AO81: 0.84615385 | AP81: 0.8 | AQ81: 1.057691 | AR81: 682 | AS81: 1.25 | AT81: 1
A82: =_xlfn.XLOOKUP(Table13[[#This Row],[SAP]],'Location List'!B:B,'Location List'!G:G) -> WEST TEXAS | B82: =LEFT(Table13[[#This Row],[Sap: Loaction]],4) -> 903E | C82: =_xlfn.XLOOKUP(Table13[[#This Row],[Employee]],'Location List'!M:M,'Location List'!N:N,"",0) | D82: 10/2026 | E82: SAUL RAMIREZ(129763) | F82: 903E: Olton | G82: 2 | H82: 367 | I82: 499.55 | J82: * | K82: 52 | L82: 30 | M82: 1.7333333 | N82: 155 | O82: 14 | P82: 75 | Q82: 0.18666667 | R82: 0.19 | S82: 0.982452 | T82: 406 | U82: 2 | V82: 75 | W82: 0.026666667 | X82: 0.05 | Y82: 0.53332 | Z82: 584 | AA82: 1 | AB82: 879 | AC82: 10 | AD82: 1 | AE82: 43 | AF82: 23.7719 | AG82: 1.8089 | AH82: 8 | AI82: 0.111111 | AJ82: 0.4 | AK82: 0.277777 | AL82: 1250 | AM82: 0 | AN82: 0 | AO82: NaN | AP82: 0.8 | AQ82: 0 | AR82: 1225 | AS82: 0 | AT82: 501
A83: =_xlfn.XLOOKUP(Table13[[#This Row],[SAP]],'Location List'!B:B,'Location List'!G:G) -> SA SOUTH | B83: =LEFT(Table13[[#This Row],[Sap: Loaction]],4) -> 4723 | C83: =_xlfn.XLOOKUP(Table13[[#This Row],[Employee]],'Location List'!M:M,'Location List'!N:N,"",0) | D83: 10/2026 | E83: JASMINE HENDERSON(129689) | F83: 4723: Palo Alto | G83: 2 | H83: 369 | I83: 500.8 | J83: * | K83: 46 | L83: 40 | M83: 1.15 | N83: 517 | O83: 25 | P83: 177 | Q83: 0.14124294 | R83: 0.19 | S83: 0.743378 | T83: 719 | U83: 7 | V83: 177 | W83: 0.039548023 | X83: 0.05 | Y83: 0.79096 | Z83: 303 | AA83: 0.869565 | AB83: 1046 | AC83: 10 | AD83: 1 | AE83: 46 | AF83: 39.0538 | AG83: 1.1779 | AH83: 121 | AI83: 0.39743567 | AJ83: 0.4 | AK83: 0.993587 | AL83: 484 | AM83: 7 | AN83: 9 | AO83: 0.77777778 | AP83: 0.8 | AQ83: 0.972221 | AR83: 779 | AS83: 1.25 | AT83: 1
A84: =_xlfn.XLOOKUP(Table13[[#This Row],[SAP]],'Location List'!B:B,'Location List'!G:G) -> DFW NORTH | B84: =LEFT(Table13[[#This Row],[Sap: Loaction]],4) -> 904E | C84: =_xlfn.XLOOKUP(Table13[[#This Row],[Employee]],'Location List'!M:M,'Location List'!N:N,"",0) | D84: 10/2026 | E84: KIOME MORGAN(126213) | F84: 904E: Jefferson | G84: 2 | H84: 374 | I84: 503.7 | J84: * | K84: 58.54 | L84: 35 | M84: 1.6725714 | N84: 177 | O84: 33 | P84: 225 | Q84: 0.14666667 | R84: 0.19 | S84: 0.771926 | T84: 678 | U84: 3 | V84: 225 | W84: 0.013333333 | X84: 0.05 | Y84: 0.26666 | Z84: 1014 | AA84: 0.933333 | AB84: 985 | AC84: 10 | AD84: 1 | AE84: 41 | AF84: 37.3559 | AG84: 1.0976 | AH84: 221 | AI84: 0.611111 | AJ84: 0.4 | AK84: 1.527777 | AL84: 120 | AM84: 11 | AN84: 17 | AO84: 0.64705882 | AP84: 0.8 | AQ84: 0.808822 | AR84: 964 | AS84: 1.25 | AT84: 1
A85: =_xlfn.XLOOKUP(Table13[[#This Row],[SAP]],'Location List'!B:B,'Location List'!G:G) -> KS/OK | B85: =LEFT(Table13[[#This Row],[Sap: Loaction]],4) -> 966D | C85: =_xlfn.XLOOKUP(Table13[[#This Row],[Employee]],'Location List'!M:M,'Location List'!N:N,"",0) | D85: 10/2026 | E85: JOSHUA SEVERN(117574) | F85: 966D: Sapulpa | G85: 2 | H85: 383 | I85: 508.25 | J85: * | K85: 29.17 | L85: 40 | M85: 0.72925 | N85: 905 | O85: 35 | P85: 210 | Q85: 0.16666667 | R85: 0.19 | S85: 0.877189 | T85: 534 | U85: 9 | V85: 210 | W85: 0.042857143 | X85: 0.05 | Y85: 0.85714 | Z85: 250 | AA85: 2.833333 | AB85: 63 | AC85: 9.153846 | AD85: 55 | AE85: 39 | AF85: 54.3358 | AG85: 0.7178 | AH85: 1168 | AI85: 0.375 | AJ85: 0.4 | AK85: 0.9375 | AL85: 536 | AM85: 3 | AN85: 3 | AO85: 1 | AP85: 0.8 | AQ85: 1.25 | AR85: 1 | AS85: 1.25 | AT85: 1
A86: =_xlfn.XLOOKUP(Table13[[#This Row],[SAP]],'Location List'!B:B,'Location List'!G:G) -> MO/IA/NE | B86: =LEFT(Table13[[#This Row],[Sap: Loaction]],4) -> 3ISR | C86: =_xlfn.XLOOKUP(Table13[[#This Row],[Employee]],'Location List'!M:M,'Location List'!N:N,"",0) | D86: 10/2026 | E86: DAVID BETTGER(117960) | F86: 3ISR: Council Bluffs | G86: 2 | H86: 397 | I86: 514.65 | J86: * | K86: 79.79 | L86: 40 | M86: 1.99475 | N86: 75 | O86: 81 | P86: 368 | Q86: 0.2201087 | R86: 0.19 | S86: 1.158463 | T86: 270 | U86: 4 | V86: 368 | W86: 0.010869565 | X86: 0.05 | Y86: 0.21738 | Z86: 1087 | AA86: 0.78125 | AB86: 1122 | AC86: 9.142857 | AD86: 56 | AE86: 41 | AF86: 41.6008 | AG86: 0.9856 | AH86: 466 | AI86: 0.388034 | AJ86: 0.4 | AK86: 0.970085 | AL86: 512 | AM86: 4 | AN86: 7 | AO86: 0.57142857 | AP86: 0.8 | AQ86: 0.714285 | AR86: 1018 | AS86: 0 | AT86: 501
A87: =_xlfn.XLOOKUP(Table13[[#This Row],[SAP]],'Location List'!B:B,'Location List'!G:G) -> CENTRAL TEXAS | B87: =LEFT(Table13[[#This Row],[Sap: Loaction]],4) -> 545D | C87: =_xlfn.XLOOKUP(Table13[[#This Row],[Employee]],'Location List'!M:M,'Location List'!N:N,"",0) -> RSM | D87: 10/2026 | E87: MYTEECIA BENSON(129394) | F87: 545D: College Station | G87: 2 | H87: 415 | I87: 522.55 | J87: * | K87: 25.14 | L87: 35 | M87: 0.71828571 | N87: 912 | O87: 17 | P87: 113 | Q87: 0.15044248 | R87: 0.19 | S87: 0.7918 | T87: 652 | U87: 4 | V87: 113 | W87: 0.03539823 | X87: 0.05 | Y87: 0.70796 | Z87: 375 | AA87: 0.941176 | AB87: 975 | AC87: 10 | AD87: 1 | AE87: 24 | AF87: 24.6209 | AG87: 0.9748 | AH87: 513 | AI87: 0.41616133 | AJ87: 0.4 | AK87: 1.040402 | AL87: 432 | AM87: 9 | AN87: 9 | AO87: 1 | AP87: 0.8 | AQ87: 1.25 | AR87: 1 | AS87: 1.25 | AT87: 1
A88: =_xlfn.XLOOKUP(Table13[[#This Row],[SAP]],'Location List'!B:B,'Location List'!G:G) -> SOUTH TX/RGV | B88: =LEFT(Table13[[#This Row],[Sap: Loaction]],4) -> 536E | C88: =_xlfn.XLOOKUP(Table13[[#This Row],[Employee]],'Location List'!M:M,'Location List'!N:N,"",0) | D88: 10/2026 | E88: ANIYAH CORTEZ(128658) | F88: 536E: Beeville | G88: 2 | H88: 423 | I88: 525.2 | J88: * | K88: 39.07 | L88: 30 | M88: 1.3023333 | N88: 389 | O88: 23 | P88: 144 | Q88: 0.15972222 | R88: 0.19 | S88: 0.840642 | T88: 585 | U88: 5 | V88: 144 | W88: 0.034722222 | X88: 0.05 | Y88: 0.69444 | Z88: 391 | AA88: 0.846153 | AB88: 1068 | AC88: 5 | AD88: 151 | AE88: 19 | AF88: 25.4699 | AG88: 0.746 | AH88: 1097 | AI88: 0.5 | AJ88: 0.4 | AK88: 1.25 | AL88: 242 | AM88: 4 | AN88: 4 | AO88: 1 | AP88: 0.8 | AQ88: 1.25 | AR88: 1 | AS88: 1.25 | AT88: 1
A89: =_xlfn.XLOOKUP(Table13[[#This Row],[SAP]],'Location List'!B:B,'Location List'!G:G) -> DFW EAST | B89: =LEFT(Table13[[#This Row],[Sap: Loaction]],4) -> 6ESH | C89: =_xlfn.XLOOKUP(Table13[[#This Row],[Employee]],'Location List'!M:M,'Location List'!N:N,"",0) | D89: 10/2026 | E89: JASON RAINEY(124418) | F89: 6ESH: Chisholm Trail | G89: 2 | H89: 426 | I89: 525.8 | J89: * | K89: 58.12 | L89: 40 | M89: 1.453 | N89: 292 | O89: 62 | P89: 320 | Q89: 0.19375 | R89: 0.19 | S89: 1.019736 | T89: 366 | U89: 10 | V89: 320 | W89: 0.03125 | X89: 0.05 | Y89: 0.625 | Z89: 466 | AA89: 1.689655 | AB89: 345 | AC89: 9.222222 | AD89: 52 | AE89: 33 | AF89: 39.9028 | AG89: 0.827 | AH89: 894 | AI89: 0.125 | AJ89: 0.4 | AK89: 0.3125 | AL89: 1221 | AM89: 12 | AN89: 14 | AO89: 0.85714286 | AP89: 0.8 | AQ89: 1.071427 | AR89: 663 | AS89: 1.25 | AT89: 1
A90: =_xlfn.XLOOKUP(Table13[[#This Row],[SAP]],'Location List'!B:B,'Location List'!G:G) -> DFW EAST | B90: =LEFT(Table13[[#This Row],[Sap: Loaction]],4) -> 618E | C90: =_xlfn.XLOOKUP(Table13[[#This Row],[Employee]],'Location List'!M:M,'Location List'!N:N,"",0) | D90: 10/2026 | E90: JEREMY HUDSON(127884) | F90: 618E: Pines Road | G90: 2 | H90: 429 | I90: 527.95 | J90: * | K90: 33.27 | L90: 30 | M90: 1.109 | N90: 550 | O90: 21 | P90: 128 | Q90: 0.1640625 | R90: 0.19 | S90: 0.863484 | T90: 552 | U90: 0 | V90: 128 | W90: 0 | X90: 0.05 | Y90: 0 | Z90: 1312 | AA90: 1.75 | AB90: 317 | AC90: 2 | AD90: 160 | AE90: 34 | AF90: 32.2619 | AG90: 1.0539 | AH90: 311 | AI90: 0.6666665 | AJ90: 0.4 | AK90: 1.666665 | AL90: 77 | AM90: 4 | AN90: 7 | AO90: 0.57142857 | AP90: 0.8 | AQ90: 0.714285 | AR90: 1018 | AS90: 0 | AT90: 501
A91: =_xlfn.XLOOKUP(Table13[[#This Row],[SAP]],'Location List'!B:B,'Location List'!G:G) -> KS/OK | B91: =LEFT(Table13[[#This Row],[Sap: Loaction]],4) -> 966D | C91: =_xlfn.XLOOKUP(Table13[[#This Row],[Employee]],'Location List'!M:M,'Location List'!N:N,"",0) | D91: 10/2026 | E91: GIAN SANCHEZ(126820) | F91: 966D: Sapulpa | G91: 2 | H91: 432 | I91: 528.6 | J91: * | K91: 66.1 | L91: 40 | M91: 1.6525 | N91: 192 | O91: 65 | P91: 299 | Q91: 0.2173913 | R91: 0.19 | S91: 1.144163 | T91: 279 | U91: 5 | V91: 299 | W91: 0.016722408 | X91: 0.05 | Y91: 0.33444 | Z91: 894 | AA91: 0.852941 | AB91: 1063 | AC91: 9.571428 | AD91: 32 | AE91: 39 | AF91: 54.3358 | AG91: 0.7178 | AH91: 1168 | AI91: 0.329089 | AJ91: 0.4 | AK91: 0.822722 | AL91: 698 | AM91: 8 | AN91: 8 | AO91: 1 | AP91: 0.8 | AQ91: 1.25 | AR91: 1 | AS91: 1.25 | AT91: 1
A92: =_xlfn.XLOOKUP(Table13[[#This Row],[SAP]],'Location List'!B:B,'Location List'!G:G) -> DFW EAST | B92: =LEFT(Table13[[#This Row],[Sap: Loaction]],4) -> 0115 | C92: =_xlfn.XLOOKUP(Table13[[#This Row],[Employee]],'Location List'!M:M,'Location List'!N:N,"",0) | D92: 10/2026 | E92: VICTOR RUVALCABA(117599) | F92: 0115: Rufe Snow | G92: 2 | H92: 435 | I92: 529.15 | J92: * | K92: 64.48 | L92: 40 | M92: 1.612 | N92: 210 | O92: 32 | P92: 237 | Q92: 0.1350211 | R92: 0.19 | S92: 0.710636 | T92: 765 | U92: 9 | V92: 237 | W92: 0.037974684 | X92: 0.05 | Y92: 0.75948 | Z92: 322 | AA92: 1.482758 | AB92: 483 | AC92: 10 | AD92: 1 | AE92: 48 | AF92: 45.8458 | AG92: 1.047 | AH92: 331 | AI92: 0.24444433 | AJ92: 0.4 | AK92: 0.61111 | AL92: 919 | AP92: 0.8 | AQ92: 0 | AR92: 1225 | AS92: 0 | AT92: 501
A93: =_xlfn.XLOOKUP(Table13[[#This Row],[SAP]],'Location List'!B:B,'Location List'!G:G) -> DFW EAST | B93: =LEFT(Table13[[#This Row],[Sap: Loaction]],4) -> 0115 | C93: =_xlfn.XLOOKUP(Table13[[#This Row],[Employee]],'Location List'!M:M,'Location List'!N:N,"",0) | D93: 10/2026 | E93: DYLAN CHARLES(111755) | F93: 0115: Rufe Snow | G93: 2 | H93: 441 | I93: 531.35 | J93: * | K93: 45.05 | L93: 40 | M93: 1.12625 | N93: 540 | O93: 51 | P93: 280 | Q93: 0.18214286 | R93: 0.19 | S93: 0.958642 | T93: 436 | U93: 8 | V93: 280 | W93: 0.028571429 | X93: 0.05 | Y93: 0.57142 | Z93: 536 | AA93: 1 | AB93: 879 | AC93: 10 | AD93: 1 | AE93: 48 | AF93: 45.8458 | AG93: 1.047 | AH93: 331 | AI93: 0.39035067 | AJ93: 0.4 | AK93: 0.975875 | AL93: 494 | AP93: 0.8 | AQ93: 0 | AR93: 1225 | AS93: 0.625 | AT93: 452
...

Sheet Location List
A1: AR Store Name | B1: STORE CODE | C1: STORE NAME | D1: ADDRESS | E1: CITY | F1: STATE | G1: DISTRICT | H1: REGION | I1: AREA | J1: DM | K1: RVP | L1: ADM | M1: RSM | N1: Column1
A2: 1DST : N Texas Ave & San Jacinto Ln | B2: 1DST | C2: Texas Ave | D2: 1601 N Texas Ave, Suite 180 | E2: Bryan | F2: TX | G2: CENTRAL TEXAS | H2: CENTRAL | I2: TMOBILE AREA | J2: STEVEN MENASHE | K2: ERICA GILLIAM | L2: KEVIN STARKE | M2: SHANNON FERGUSON(124126) | N2: RSM
A3: 1DSU : Rudder's Landing | B3: 1DSU | C3: Bryan | D3: 1622 W Villa Maria Rd, Suite 100 | E3: Bryan | F3: TX | G3: CENTRAL TEXAS | H3: CENTRAL | I3: TMOBILE AREA | J3: STEVEN MENASHE | K3: ERICA GILLIAM | L3: KEVIN STARKE | M3: SHAIN HARRIS(123607) | N3: RSM
A4: 1FSC : Old San Antonio Rd & Main St | B4: 1FSC | C4: Buda | D4: 640 Old San Antonio Rd, Suite 100 | E4: Buda | F4: TX | G4: CENTRAL TEXAS | H4: CENTRAL | I4: TMOBILE AREA | J4: STEVEN MENASHE | K4: ERICA GILLIAM | L4: KEVIN STARKE | M4: JACOB MINOR(124926) | N4: RSM
A5: 1FSS : Belterra Village | B5: 1FSS | C5: Belterra | D5: 165 Hargraves Dr, Suite P200 | E5: Austin | F5: TX | G5: CENTRAL TEXAS | H5: CENTRAL | I5: TMOBILE AREA | J5: STEVEN MENASHE | K5: ERICA GILLIAM | L5: KEVIN STARKE | M5: ANGELICA ESPARZA(122869) | N5: RSM
A6: 545D : State Hwy 6 & Arrington Rd | B6: 545D | C6: College Station | D6: 4400 Highway 6 S, Suite 400 | E6: College Station | F6: TX | G6: CENTRAL TEXAS | H6: CENTRAL | I6: TMOBILE AREA | J6: STEVEN MENASHE | K6: ERICA GILLIAM | L6: KEVIN STARKE | M6: MYTEECIA BENSON(129394) | N6: RSM
A7: 961F : State Hwy 71 & W Hwy 159 | B7: 961F | C7: Highway 71 | D7: 2001 W State Highway 71, Suite D | E7: La Grange | F7: TX | G7: CENTRAL TEXAS | H7: CENTRAL | I7: TMOBILE AREA | J7: STEVEN MENASHE | K7: ERICA GILLIAM | L7: KEVIN STARKE | M7: REUBEN RICH JR(128312) | N7: RSM
A8: 1DSD : Constitution & US 190 | B8: 1DSD | C8: Copperas Cove | D8: 210 Constitution Dr, Building B | E8: Copperas Cove | F8: TX | G8: CENTRAL TEXAS | H8: CENTRAL | I8: TMOBILE AREA | J8: STEVEN MENASHE | K8: ERICA GILLIAM | L8: KEVIN STARKE | M8: RENE ARREDONDO(105152) | N8: RSM
A9: 1DSF : Stan Schlueter & Jake Spoon | B9: 1DSF | C9: Killeen | D9: 3650 W Stan Schlueter Loop, Suite 100 | E9: Killeen | F9: TX | G9: CENTRAL TEXAS | H9: CENTRAL | I9: TMOBILE AREA | J9: STEVEN MENASHE | K9: ERICA GILLIAM | L9: KEVIN STARKE | M9: JESSICA BENSKIN(105163) | N9: RSM
A10: 1DSG : N Main St & Carlos G Parker Blvd NW | B10: 1DSG | C10: Taylor | D10: 3605 N Main St, Suite 36-102 | E10: Taylor | F10: TX | G10: CENTRAL TEXAS | H10: CENTRAL | I10: TMOBILE AREA | J10: STEVEN MENASHE | K10: ERICA GILLIAM | L10: KEVIN STARKE | M10: LAMONICA ALVARADO(106418) | N10: RSM
A11: 1FSH : Ring Dr & Saint Mary Dr | B11: 1FSH | C11: Manor | D11: 11828 Ring Dr, Suite 109 | E11: Manor | F11: TX | G11: CENTRAL TEXAS | H11: CENTRAL | I11: TMOBILE AREA | J11: STEVEN MENASHE | K11: ERICA GILLIAM | L11: KEVIN STARKE | M11: SHANNON VOORHEES(115363) | N11: RSM
A12: 1FSI : US Hwy 281 & Trade St | B12: 1FSI | C12: Marble Falls | D12: 2511 US Highway 281, Suite 600 | E12: Marble Falls | F12: TX | G12: CENTRAL TEXAS | H12: CENTRAL | I12: TMOBILE AREA | J12: STEVEN MENASHE | K12: ERICA GILLIAM | L12: KEVIN STARKE | M12: CHRISTOPHER SELLE(124211) | N12: RSM
... A23: 465D : W Stonebrook Pkwy & Fm 423 | B23: 465D | C23: Stonebrook | D23: 252 W Stonebrook Parkway, Suite 570 | E23: Frisco | F23: TX | G23: DFW NORTH | H23: CENTRAL | I23: TMOBILE AREA | J23: BEAU CUMBIE | K23: ERICA GILLIAM | L23: KEVIN STARKE | M23: ZACHARY ANDUHA(129203) | N23: RSM
A24: 904E : S Jefferson Ave & E Ferguson | B24: 904E | C24: Jefferson | D24: 618 S Jefferson Ave | E24: Mt Pleasant | F24: TX | G24: DFW NORTH | H24: CENTRAL | I24: TMOBILE AREA | J24: BEAU CUMBIE | K24: ERICA GILLIAM | L24: KEVIN STARKE | N24: RSM
A25: 1239 : Cedar Ridge & Wheatland Rd | B25: 1239 | C25: Duncanville | D25: 327 S Cedar Ridge Drive | E25: Duncanville | F25: TX | G25: DFW NORTH | H25: CENTRAL | I25: TMOBILE AREA | J25: BEAU CUMBIE | K25: ERICA GILLIAM | L25: KEVIN STARKE | M25: ALEXA ORTEGA(123577) | N25: RSM
A26: 1BSA : E Ennis Ave & Laurel St | B26: 1BSA | C26: Ennis | D26: 600 E Ennis Ave, Suite B | E26: Ennis | F26: TX | G26: DFW NORTH | H26: CENTRAL | I26: TMOBILE AREA | J26: BEAU CUMBIE | K26: ERICA GILLIAM | L26: KEVIN STARKE | M26: CECILIA ANDRADE(123160) | N26: RSM
A27: 1BSE : E Ovilla Rd & Harris Ave | B27: 1BSE | C27: Red Oak | D27: 102 E Ovilla Rd, Suite B4 | E27: Ennis | F27: TX | G27: DFW NORTH | H27: CENTRAL | I27: TMOBILE AREA | J27: BEAU CUMBIE | K27: ERICA GILLIAM | L27: KEVIN STARKE | M27: DESTINY PAGE(122505) | N27: RSM
A28: 5429 : 7th Ave & S 34th Street | B28: 5429 | C28: Seventh Ave | D28: 2521 W 7th Ave, Suite B | E28: Corsicana | F28: TX | G28: DFW NORTH | H28: CENTRAL | I28: TMOBILE AREA | J28: BEAU CUMBIE | K28: ERICA GILLIAM | L28: KEVIN STARKE | M28: JASMINE KENNEMORE(126167) | N28: RSM
A29: 256E : N Wolfe Nursery Rd & Washington St | B29: 256E | C29: Stephenville | D29: 100 Wolfe Nursery Rd, Suite 114 | E29: Stephenville | F29: TX | G29: DFW NORTH | H29: CENTRAL | I29: TMOBILE AREA | J29: BEAU CUMBIE | K29: ERICA GILLIAM | L29: KEVIN STARKE | M29: ANDREW BROWN(111050) | N29: RSM
A30: 1CSM : S Main St & Adams Dr | B30: 1CSM | C30: Weatherford | D30: 1950 S Main St | E30: Weatherford | F30: TX | G30: DFW NORTH | H30: CENTRAL | I30: TMOBILE AREA | J30: BEAU CUMBIE | K30: ERICA GILLIAM | L30: KEVIN STARKE | M30: TYLER BEAL(109960) | N30: RSM
A31: 211E : Henderson St & Ridgeway Dr | B31: 211E | C31: Cleburne | D31: 1502 W Henderson St, Suite B | E31: Cleburne | F31: TX | G31: DFW NORTH | H31: CENTRAL | I31: TMOBILE AREA | J31: BEAU CUMBIE | K31: ERICA GILLIAM | L31: KEVIN STARKE | M31: KASSIDY JEFFERSON(126219) | N31: RSM
A32: 924C : Sh 377 & Acton Hwy | B32: 924C | C32: Granbury | D32: 3803 E Highway 377, Suite 100 | E32: Granbury | F32: TX | G32: DFW NORTH | H32: CENTRAL | I32: TMOBILE AREA | J32: BEAU CUMBIE | K32: ERICA GILLIAM | L32: KEVIN STARKE | N32: RSM
A33: 407D : E Prospect Ave & N 5th Street | B33: 407D | C33: Ponca City | D33: 901 E Prospect, Suite C-12 | E33: Ponca City | F33: OK | G33: KS/OK | H33: CENTRAL | I33: TMOBILE AREA | J33: JOE MCKEE | K33: ERICA GILLIAM | L33: KEVIN STARKE | M33: CAYCE LEWIS(116920) | N33: RSM
A34: 849C : Geo Washington Bvld & E Harry St | B34: 849C | C34: George Washington | D34: 1600 George Washington Boulevard | E34: Wichita | F34: KS | G34: KS/OK | H34: CENTRAL | I34: TMOBILE AREA | J34: JOE MCKEE | K34: ERICA GILLIAM | L34: KEVIN STARKE | M34: JAIMIE CALALAY(116983) | N34: RSM
A35: 857C : S 9th Street & E Schilling Rd | B35: 857C | C35: Schilling | D35: 3015 S 9th Street | E35: Salina | F35: KS | G35: KS/OK | H35: CENTRAL | I35: TMOBILE AREA | J35: JOE MCKEE | K35: ERICA GILLIAM | L35: KEVIN STARKE | M35: AUSTIN RALPH(126226) | N35: RSM
A36: 966D : W Taft Ave & Main St | B36: 966D | C36: Sapulpa | D36: 126 W Taft Avenue, Suite 126 | E36: Sapulpa | F36: OK | G36: KS/OK | H36: CENTRAL | I36: TMOBILE AREA | J36: JOE MCKEE | K36: ERICA GILLIAM | L36: KEVIN STARKE | M36: MARQUIS POINDEXTER(116655) | N36: RSM
A37: 114E : The Shoppes at Chisholm Trail | B37: 114E | C37: Chickasha | D37: 2123 S 4th Street | E37: Chickasha | F37: OK | G37: KS/OK | H37: CENTRAL | I37: TMOBILE AREA | J37: JOE MCKEE | K37: ERICA GILLIAM | L37: KEVIN STARKE | M37: RICHARD WASHINGTON(117438) | N37: RSM
A38: 4781 : Shawnee Marketplace | B38: 4781 | C38: Market Place | D38: 4850 Market Place Boulevard, Suite 300 | E38: Shawnee | F38: OK | G38: KS/OK | H38: CENTRAL | I38: TMOBILE AREA | J38: JOE MCKEE | K38: ERICA GILLIAM | L38: KEVIN STARKE | M38: AUSTIN HIROM(114277) | N38: RSM
A39: 4789 : Westgate Plaza | B39: 4789 | C39: Owen Garriott | D39: 2312 A W Owen K Garriott Rd | E39: Enid | F39: OK | G39: KS/OK | H39: CENTRAL | I39: TMOBILE AREA | J39: JOE MCKEE | K39: ERICA GILLIAM | L39: KEVIN STARKE | M39: JAIMIE CALALAY(116983) | N39: RSM
A40: 4DSC : Hwy 152 and Sara Rd | B40: 4DSC | C40: Mustang | D40: 1001 E State Highway 152, Suite 103 | E40: Mustang | F40: OK | G40: KS/OK | H40: CENTRAL | I40: TMOBILE AREA | J40: JOE MCKEE | K40: ERICA GILLIAM | L40: KEVIN STARKE | M40: AUSTIN HIROM(114277) | N40: RSM
A41: 5280 : I-40 and Garth Brooks | B41: 5280 | C41: Garth Brooks Blvd | D41: 1299 Garth Brooks Boulevard | E41: Yukon | F41: OK | G41: KS/OK | H41: CENTRAL | I41: TMOBILE AREA | J41: JOE MCKEE | K41: ERICA GILLIAM | L41: KEVIN STARKE | M41: RICHARD WASHINGTON(117438) | N41: RSM
A42: 586D : Ardmore Commons | B42: 586D | C42: Ardmore | D42: 2401 12th Ave NW, Suite 115 | E42: Ardmore | F42: OK | G42: KS/OK | H42: CENTRAL | I42: TMOBILE AREA | J42: JOE MCKEE | K42: ERICA GILLIAM | L42: KEVIN STARKE | M42: DAVID LENT(121205) | N42: RSM
A43: 990F : Wrangler & Harvey | B43: 990F | C43: Wrangler | D43: 1600 Highway 9 | E43: Seminole | F43: OK | G43: KS/OK | H43: CENTRAL | I43: TMOBILE AREA | J43: JOE MCKEE | K43: ERICA GILLIAM | L43: KEVIN STARKE | M43: DAVID LENT(121205) | N43: RSM
A44: 3ISS : Asbury Rd & Holiday Dr | B44: 3ISS | C44: Dubuque | D44: 4840 Asbury Rd | E44: Dubuque | F44: IA | G44: MO/IA/NE | H44: CENTRAL | I44: TMOBILE AREA | J44: BILL CLARK | K44: ERICA GILLIAM | L44: KEVIN STARKE | M44: JAMES SNIDER(123567) | N44: RSM
